<?xml version="1.0" encoding="utf-8"?>
<robot name="ur10e_robot">
  <!--
    This file models the base kinematic chain of a UR robot, which then gets
    parameterised by various configuration files to convert it into a UR3(e),
    UR5(e), UR10(e), UR16e, UR20 or UR30.

    NOTE: the default kinematic parameters (ie: link lengths, frame locations,
    offets, etc) do not correspond to any particular robot. They are defaults
    only. There WILL be non-zero offsets between the Forward Kinematics results
    in TF (ie: robot_state_publisher) and the values reported by the Teach
    Pendant.

    For accurate (and robot-specific) transforms, the 'kinematics_parameters_file'
    parameter MUST point to a .yaml file containing the appropriate values for
    the targetted robot.

    If using the UniversalRobots/Universal_Robots_ROS_Driver, follow the steps
    described in the readme of that repository to extract the kinematic
    calibration from the controller and generate the required .yaml file.

    Main author of the migration to yaml configs: Ludovic Delval.

    Contributors to previous versions (in no particular order):

     - Felix Messmer
     - Kelsey Hawkins
     - Wim Meeussen
     - Shaun Edwards
     - Nadia Hammoudeh Garcia
     - Dave Hershberger
     - G. vd. Hoorn
     - Philip Long
     - Dave Coleman
     - Miguel Prada
     - Mathias Luedtke
     - Marcel Schnirring
     - Felix von Drigalski
     - Felix Exner
     - Jimmy Da Silva
     - Ajit Krisshna N L
     - Muhammad Asif Rana
  -->
  <!-- links: main serial chain -->
  <link name="base_link"/>
  <link name="base_link_inertia">
    <visual>
      <origin rpy="0 0 3.14159265359" xyz="0 0 0"/>
      <geometry>
        <mesh filename="../../arms/ur10e/meshes/visual/base.obj"/>
      </geometry>
    </visual>
    <collision>
      <origin rpy="0 0 3.14159265359" xyz="0 0 0"/>
      <geometry>
        <mesh filename="../../arms/ur10e/meshes/collision/base.obj"/>
      </geometry>
    </collision>
    <inertial>
      <mass value="4.0"/>
      <origin rpy="0 0 0" xyz="0 0 0"/>
      <inertia ixx="0.0061063308908" ixy="0.0" ixz="0.0" iyy="0.0061063308908" iyz="0.0" izz="0.01125"/>
    </inertial>
  </link>
  <link name="shoulder_link">
    <visual>
      <origin rpy="0 0 3.14159265359" xyz="0 0 0"/>
      <geometry>
        <mesh filename="../../arms/ur10e/meshes/visual/shoulder.obj"/>
      </geometry>
    </visual>
    <collision>
      <origin rpy="0 0 3.14159265359" xyz="0 0 0"/>
      <geometry>
        <mesh filename="../../arms/ur10e/meshes/collision/shoulder.obj"/>
      </geometry>
    </collision>
    <inertial>
      <mass value="7.778"/>
      <origin rpy="0 0 0" xyz="0 0 0"/>
      <inertia ixx="0.0314743125769" ixy="0.0" ixz="0.0" iyy="0.0314743125769" iyz="0.0" izz="0.021875625"/>
    </inertial>
  </link>
  <link name="upper_arm_link">
    <visual>
      <origin rpy="1.57079632679 0 -1.57079632679" xyz="0 0 0.1762"/>
      <geometry>
        <mesh filename="../../arms/ur10e/meshes/visual/upperarm.obj"/>
      </geometry>
    </visual>
    <collision>
      <origin rpy="1.57079632679 0 -1.57079632679" xyz="0 0 0.1762"/>
      <geometry>
        <mesh filename="../../arms/ur10e/meshes/collision/upperarm.obj"/>
      </geometry>
    </collision>
    <inertial>
      <mass value="12.93"/>
      <origin rpy="0 1.57079632679 0" xyz="-0.306 0.0 0.175"/>
      <inertia ixx="0.421753803798" ixy="0.0" ixz="0.0" iyy="0.421753803798" iyz="0.0" izz="0.036365625"/>
    </inertial>
  </link>
  <link name="forearm_link">
    <visual>
      <origin rpy="1.57079632679 0 -1.57079632679" xyz="0 0 0.0393"/>
      <geometry>
        <mesh filename="../../arms/ur10e/meshes/visual/forearm.obj"/>
      </geometry>
    </visual>
    <collision>
      <origin rpy="1.57079632679 0 -1.57079632679" xyz="0 0 0.0393"/>
      <geometry>
        <mesh filename="../../arms/ur10e/meshes/collision/forearm.obj"/>
      </geometry>
    </collision>
    <inertial>
      <mass value="3.87"/>
      <origin rpy="0 1.57079632679 0" xyz="-0.285775 0.0 0.0393"/>
      <inertia ixx="0.110793025489" ixy="0.0" ixz="0.0" iyy="0.110793025489" iyz="0.0" izz="0.010884375"/>
    </inertial>
  </link>
  <link name="wrist_1_link">
    <visual>
      <origin rpy="1.57079632679 0 0" xyz="0 0 -0.135"/>
      <geometry>
        <mesh filename="../../arms/ur10e/meshes/visual/wrist1.obj"/>
      </geometry>
    </visual>
    <collision>
      <origin rpy="1.57079632679 0 0" xyz="0 0 -0.135"/>
      <geometry>
        <mesh filename="../../arms/ur10e/meshes/collision/wrist1.obj"/>
      </geometry>
    </collision>
    <inertial>
      <mass value="1.96"/>
      <origin rpy="0 0 0" xyz="0 0 0"/>
      <inertia ixx="0.0051082479567" ixy="0.0" ixz="0.0" iyy="0.0051082479567" iyz="0.0" izz="0.0055125"/>
    </inertial>
  </link>
  <link name="wrist_2_link">
    <visual>
      <origin rpy="0 0 0" xyz="0 0 -0.12"/>
      <geometry>
        <mesh filename="../../arms/ur10e/meshes/visual/wrist2.obj"/>
      </geometry>
    </visual>
    <collision>
      <origin rpy="0 0 0" xyz="0 0 -0.12"/>
      <geometry>
        <mesh filename="../../arms/ur10e/meshes/collision/wrist2.obj"/>
      </geometry>
    </collision>
    <inertial>
      <mass value="1.96"/>
      <origin rpy="0 0 0" xyz="0 0 0"/>
      <inertia ixx="0.0051082479567" ixy="0.0" ixz="0.0" iyy="0.0051082479567" iyz="0.0" izz="0.0055125"/>
    </inertial>
  </link>
  <link name="wrist_3_link">
    <visual>
      <origin rpy="1.57079632679 0 0" xyz="0 0 -0.1168"/>
      <geometry>
        <mesh filename="../../arms/ur10e/meshes/visual/wrist3.obj"/>
      </geometry>
    </visual>
    <collision>
      <origin rpy="1.57079632679 0 0" xyz="0 0 -0.1168"/>
      <geometry>
        <mesh filename="../../arms/ur10e/meshes/collision/wrist3.obj"/>
      </geometry>
    </collision>
    <inertial>
      <mass value="0.202"/>
      <origin rpy="0 0 0" xyz="0.0 0.0 -0.025"/>
      <inertia ixx="0.000144345775595" ixy="0.0" ixz="0.0" iyy="0.000144345775595" iyz="0.0" izz="0.000204525"/>
    </inertial>
  </link>
  <!-- joints: main serial chain -->
  <joint name="base_link-base_link_inertia" type="fixed">
    <parent link="base_link"/>
    <child link="base_link_inertia"/>
    <!-- 'base_link' is REP-103 aligned (so X+ forward), while the internal
           frames of the robot/controller have X+ pointing backwards.
           Use the joint between 'base_link' and 'base_link_inertia' (a dummy
           link/frame) to introduce the necessary rotation over Z (of pi rad).
      -->
    <origin rpy="0 0 3.14159265359" xyz="0 0 0"/>
  </joint>
  <joint name="shoulder_pan_joint" type="revolute">
    <parent link="base_link_inertia"/>
    <child link="shoulder_link"/>
    <origin rpy="0 0 0" xyz="0 0 0.1807"/>
    <axis xyz="0 0 1"/>
    <limit effort="330.0" lower="-6.28318530718" upper="6.28318530718" velocity="2.09439510239"/>
    <dynamics damping="0" friction="0"/>
  </joint>
  <joint name="shoulder_lift_joint" type="revolute">
    <parent link="shoulder_link"/>
    <child link="upper_arm_link"/>
    <origin rpy="1.570796327 0 0" xyz="0 0 0"/>
    <axis xyz="0 0 1"/>
    <limit effort="330.0" lower="-6.28318530718" upper="6.28318530718" velocity="2.09439510239"/>
    <dynamics damping="0" friction="0"/>
  </joint>
  <joint name="elbow_joint" type="revolute">
    <parent link="upper_arm_link"/>
    <child link="forearm_link"/>
    <origin rpy="0 0 0" xyz="-0.6127 0 0"/>
    <axis xyz="0 0 1"/>
    <limit effort="150.0" lower="-3.14159265359" upper="3.14159265359" velocity="3.14159265359"/>
    <dynamics damping="0" friction="0"/>
  </joint>
  <joint name="wrist_1_joint" type="revolute">
    <parent link="forearm_link"/>
    <child link="wrist_1_link"/>
    <origin rpy="0 0 0" xyz="-0.57155 0 0.17415"/>
    <axis xyz="0 0 1"/>
    <limit effort="56.0" lower="-6.28318530718" upper="6.28318530718" velocity="3.14159265359"/>
    <dynamics damping="0" friction="0"/>
  </joint>
  <joint name="wrist_2_joint" type="revolute">
    <parent link="wrist_1_link"/>
    <child link="wrist_2_link"/>
    <origin rpy="1.570796327 0 0" xyz="0 -0.11985 -2.45816459076e-11"/>
    <axis xyz="0 0 1"/>
    <limit effort="56.0" lower="-6.28318530718" upper="6.28318530718" velocity="3.14159265359"/>
    <dynamics damping="0" friction="0"/>
  </joint>
  <joint name="wrist_3_joint" type="revolute">
    <parent link="wrist_2_link"/>
    <child link="wrist_3_link"/>
    <origin rpy="1.57079632659 3.14159265359 3.14159265359" xyz="0 0.11655 -2.39048045935e-11"/>
    <axis xyz="0 0 1"/>
    <limit effort="56.0" lower="-6.28318530718" upper="6.28318530718" velocity="3.14159265359"/>
    <dynamics damping="0" friction="0"/>
  </joint>
  <!-- ROS-Industrial 'base' frame: base_link to UR 'Base' Coordinates transform -->
  <link name="base"/>
  <joint name="base_link-base_fixed_joint" type="fixed">
    <!-- Note the rotation over Z of pi radians: as base_link is REP-103
           aligned (ie: has X+ forward, Y+ left and Z+ up), this is needed
           to correctly align 'base' with the 'Base' coordinate system of
           the UR controller.
      -->
    <origin rpy="0 0 3.14159265359" xyz="0 0 0"/>
    <parent link="base_link"/>
    <child link="base"/>
  </joint>
  <!-- ROS-Industrial 'flange' frame: attachment point for EEF models -->
  <link name="ee_link"/>
  <joint name="wrist_3-flange" type="fixed">
    <parent link="wrist_3_link"/>
    <child link="ee_link"/>
    <origin rpy="1.57079632679 -1.57079632679 0" xyz="0 0 0"/>
  </joint>

  <!-- allegro hand -->
  <joint name="arm_hand_joint" type="fixed">
    <parent link="ee_link"/>
    <child link="allegro_base_link"/>
    <origin xyz="0.085 0.0 -0.025" rpy="0 1.57079 0 "/>
  </joint>

  <link name="allegro_base_link">
    <inertial>
      <mass value="0.4154"/>
      <origin rpy="0 0 0" xyz="0 0 0"/>
      <inertia ixx="1e-4" ixy="0" ixz="0" iyy="1e-4" iyz="0" izz="1e-4"/>
    </inertial>
    <visual>
      <geometry>
        <mesh filename="../../hands/allegro_hand/meshes/visual/base_link.obj"/>
      </geometry>
      <origin rpy="0 0 0" xyz="0 0 0 "/>
    </visual>
    <collision>
      <origin rpy="0 0 0" xyz="-0.009 0.0 -0.023"/>
      <geometry>
        <box size="0.0414 0.112 0.0448"/>
      </geometry>
    </collision>
    <collision>
      <origin rpy="0 0 0" xyz="-0.009 -0.0253 -0.0667"/>
      <geometry>
        <box size="0.0414 0.0538 0.0428"/>
      </geometry>
    </collision>
    <collision>
      <origin rpy="0 0 0" xyz="-0.009300 -0.00557 -0.08874"/>
      <geometry>
        <box size="0.0414 0.0720 0.013"/>
      </geometry>
    </collision>
  </link> <!--  virtual link-->
  <link name="palm"/>
  <joint name="palm_joint" type="fixed">
    <parent link="allegro_base_link"/>
    <child link="palm"/>
    <origin rpy="0.00000 -0.00000 0.00000" xyz="0 0 -0.065"/>
  </joint> <!--  virtual link-->
  <link name="wrist"/>
  <joint name="wrist_joint" type="fixed">
    <origin rpy="0 0 0" xyz="0 0 -0.03"/>
    <parent link="palm"/>
    <child link="wrist"/>
  </joint>
  <link name="link_0.0">
    <visual>
      <geometry>
        <mesh filename="../../hands/allegro_hand/meshes/visual/link_0.0.obj"/>
      </geometry>
    </visual>
    <collision>
      <geometry>
        <box size="0.0196 0.0275 0.0164"/>
      </geometry>
      <origin rpy="0 0 0" xyz="0 0 0.0082"/>
    </collision>
    <inertial>
      <mass value="0.0119"/>
      <origin xyz="0 0 0" rpy="0 0 0"/>
      <inertia ixx="1.01666658333e-06" ixy="0.0" ixz="0.0" iyy="6.47677333333e-07" iyz="0.0" izz="1.01666658333e-06"/>
    </inertial>
  </link>
  <joint name="joint_0.0" type="revolute">
    <axis xyz="0 0 1"/>
    <limit effort="10" lower="-0.47" upper="0.47" velocity="3.14"/>
    <parent link="allegro_base_link"/>
    <child link="link_0.0"/>
    <origin rpy="-0.08726646255 0 0" xyz="0 0.0435 -0.001542"/>
  </joint>
  <link name="link_1.0">
    <inertial>
      <mass value="0.065"/>
      <origin xyz="0 0 0" rpy="0 0 0"/>
      <inertia ixx="7.95654166667e-05" ixy="1.7199e-05" ixz="8.75875e-06" iyy="2.47088833333e-05" iyz="2.413125e-05" izz="7.95654166667e-05"/>
    </inertial>
    <visual>
      <geometry>
        <mesh filename="../../hands/allegro_hand/meshes/visual/link_1.0.obj"/>
      </geometry>
    </visual>
    <collision>
      <geometry>
        <box size="0.0196 0.0275 0.054"/>
      </geometry>
      <origin rpy="0 0 0" xyz="0 0 0.027"/>
    </collision>
  </link>
  <joint name="joint_1.0" type="revolute">
    <limit effort="10" lower="-0.196" upper="1.61" velocity="3.14"/>
    <axis xyz="0 1 0"/>
    <parent link="link_0.0"/>
    <child link="link_1.0"/>
    <origin xyz="0 0 0.0164"/>
  </joint>
  <link name="link_2.0">
    <inertial>
      <mass value="0.0355"/>
      <origin xyz="0 0 0" rpy="0 0 0"/>
      <inertia ixx="2.63979183333e-05" ixy="6.67968e-06" ixz="4.783625e-06" iyy="1.34948516667e-05" iyz="9.372e-06" izz="2.63979183333e-05"/>
    </inertial>
    <visual>
      <geometry>
        <mesh filename="../../hands/allegro_hand/meshes/visual/link_2.0.obj"/>
      </geometry>
    </visual>
    <collision>
      <geometry>
        <box size="0.0196 0.0275 0.0384"/>
      </geometry>
      <origin rpy="0 0 0" xyz="0 0 0.0192"/>
    </collision>
  </link>
  <joint name="joint_2.0" type="revolute">
    <axis xyz="0 1 0"/>
    <limit effort="10" lower="-0.174" upper="1.709" velocity="3.14"/>
    <parent link="link_1.0"/>
    <child link="link_2.0"/>
    <origin xyz="0 0 0.054"/>
  </joint>
  <link name="link_3.0">
    <visual>
      <geometry>
        <mesh filename="../../hands/allegro_hand/meshes/visual/link_3.0.obj"/>
      </geometry>
    </visual>
    <collision>
      <geometry>
        <box size="0.0196 0.0269 0.022"/>
      </geometry>
      <origin rpy="0 0 0" xyz="0 0 0.0047"/>
    </collision>
    <inertial>
      <origin rpy="0 0 0" xyz="0 0 0.01335"/>
      <mass value="0.02"/>
      <inertia ixx="1e-5" ixy="0.0" ixz="0.0" iyy="2e-5" iyz="0.0" izz="2e-5"/>
    </inertial>
  </link>
  <joint name="joint_3.0" type="revolute">
    <axis xyz="0 1 0"/>
    <limit effort="10" lower="-0.227" upper="1.618" velocity="3.14"/>
    <parent link="link_2.0"/>
    <child link="link_3.0"/>
    <origin xyz="0 0 0.0384"/>
  </joint>
  <link name="link_3.0_tip">
    <inertial>
      <mass value="0.0168"/>
      <origin xyz="0 0 0" rpy="0 0 0"/>
      <inertia ixx="9.68e-07" ixy="0" ixz="0" iyy="9.68e-07" iyz="0" izz="9.68e-07"/>
    </inertial>
    <visual>
      <origin rpy="0 0 0" xyz="0 0 -0.012"/>
      <geometry>
        <mesh filename="../../hands/allegro_hand/meshes/visual/link_tip.obj"/>
      </geometry>
    </visual>
    <collision>
      <origin rpy="0 0 0" xyz="0 0 -0.012"/>
      <geometry>
        <mesh filename="../../hands/allegro_hand/meshes/collision/link_tip.obj"/>
      </geometry>
    </collision>
  </link>
  <joint name="joint_3.0_tip" type="fixed">
    <parent link="link_3.0"/>
    <child link="link_3.0_tip"/>
    <origin rpy="0 0 0" xyz="0 0 0.0387"/>
  </joint>
  <link name="link_4.0">
    <inertial>
      <mass value="0.005"/>
      <origin xyz="0 0 0"/>
      <inertia ixx="5.1458e-05" iyy="5.1458e-05" izz="6.125e-05" ixy="0" ixz="0" iyz="0"/>
    </inertial>
    <visual>
      <geometry>
        <mesh filename="../../hands/allegro_hand/meshes/visual/link_0.0.obj"/>
      </geometry>
    </visual>
    <collision>
      <geometry>
        <box size="0.0196 0.0275 0.0164"/>
      </geometry>
      <origin rpy="0 0 0" xyz="0 0 0.0082"/>
    </collision>
  </link>
  <joint name="joint_4.0" type="revolute">
    <axis xyz="0 0 1"/>
    <limit effort="10" lower="-0.47" upper="0.47" velocity="3.14"/>
    <parent link="allegro_base_link"/>
    <child link="link_4.0"/>
    <origin rpy="0.0 0 0" xyz="0 0 0.0007"/>
  </joint>
  <link name="link_5.0">
    <inertial>
      <mass value="0.065"/>
      <origin xyz="0 0 0" rpy="0 0 0"/>
      <inertia ixx="7.95654166667e-05" ixy="1.7199e-05" ixz="8.75875e-06" iyy="2.47088833333e-05" iyz="2.413125e-05" izz="7.95654166667e-05"/>
    </inertial>
    <visual>
      <geometry>
        <mesh filename="../../hands/allegro_hand/meshes/visual/link_1.0.obj"/>
      </geometry>
    </visual>
    <collision>
      <geometry>
        <box size="0.0196 0.0275 0.054"/>
      </geometry>
      <origin rpy="0 0 0" xyz="0 0 0.027"/>
    </collision>
  </link>
  <joint name="joint_5.0" type="revolute">
    <limit effort="10" lower="-0.196" upper="1.61" velocity="3.14"/>
    <axis xyz="0 1 0"/>
    <parent link="link_4.0"/>
    <child link="link_5.0"/>
    <origin xyz="0 0 0.0164"/>
  </joint>
  <link name="link_6.0">
    <inertial>
      <mass value="0.0355"/>
      <origin xyz="0 0 0" rpy="0 0 0"/>
      <inertia ixx="2.63979183333e-05" ixy="6.67968e-06" ixz="4.783625e-06" iyy="1.34948516667e-05" iyz="9.372e-06" izz="2.63979183333e-05"/>
    </inertial>
    <visual>
      <geometry>
        <mesh filename="../../hands/allegro_hand/meshes/visual/link_2.0.obj"/>
      </geometry>
    </visual>
    <collision>
      <geometry>
        <box size="0.0196 0.0275 0.0384"/>
      </geometry>
      <origin rpy="0 0 0" xyz="0 0 0.0192"/>
    </collision>
  </link>
  <joint name="joint_6.0" type="revolute">
    <axis xyz="0 1 0"/>
    <limit effort="10" lower="-0.174" upper="1.709" velocity="3.14"/>
    <parent link="link_5.0"/>
    <child link="link_6.0"/>
    <origin xyz="0 0 0.054"/>
  </joint>
  <link name="link_7.0">
    <inertial>
      <mass value="0.0388"/>
      <origin xyz="0 0 0" rpy="0 0 0"/>
      <inertia ixx="3.29223173333e-05" ixy="8.042076e-06" ixz="5.2283e-06" iyy="1.47493026667e-5" iyz="1.1283525e-5" izz="3.29223173333e-05"/>
    </inertial>
    <visual>
      <geometry>
        <mesh filename="../../hands/allegro_hand/meshes/visual/link_3.0.obj"/>
      </geometry>
    </visual>
    <collision>
      <geometry>
        <box size="0.0196 0.0269 0.022"/>
      </geometry>
      <origin rpy="0 0 0" xyz="0 0 0.0047"/>
    </collision>
  </link>
  <joint name="joint_7.0" type="revolute">
    <axis xyz="0 1 0"/>
    <limit effort="10" lower="-0.227" upper="1.618" velocity="3.14"/>
    <parent link="link_6.0"/>
    <child link="link_7.0"/>
    <origin xyz="0 0 0.0384"/>
  </joint>
  <link name="link_7.0_tip">
    <inertial>
      <mass value="0.0096"/>
      <origin xyz="0 0 0" rpy="0 0 0"/>
      <inertia ixx="4.701248e-06" ixy="1.255968e-06" ixz="1.2936e-06" iyy="3.649312e-06" iyz="1.7622e-06" izz="4.701248e-06"/>
    </inertial>
    <visual>
      <origin rpy="0 0 0" xyz="0 0 -0.012"/>
      <geometry>
        <mesh filename="../../hands/allegro_hand/meshes/visual/link_tip.obj"/>
      </geometry>
    </visual>
    <collision>
      <origin rpy="0 0 0" xyz="0 0 -0.012"/>
      <geometry>
        <mesh filename="../../hands/allegro_hand/meshes/collision/link_tip.obj"/>
      </geometry>
    </collision>
  </link>
  <joint name="joint_7.0_tip" type="fixed">
    <parent link="link_7.0"/>
    <child link="link_7.0_tip"/>
    <origin rpy="0 0 0" xyz="0 0 0.0387"/>
  </joint>
  <link name="link_8.0">
    <inertial>
      <mass value="0.005"/>
      <origin xyz="0 0 0"/>
      <inertia ixx="5.1458e-05" iyy="5.1458e-05" izz="6.125e-05" ixy="0" ixz="0" iyz="0"/>
    </inertial>
    <visual>
      <geometry>
        <mesh filename="../../hands/allegro_hand/meshes/visual/link_0.0.obj"/>
      </geometry>
    </visual>
    <collision>
      <geometry>
        <box size="0.0196 0.0275 0.0164"/>
      </geometry>
      <origin rpy="0 0 0" xyz="0 0 0.0082"/>
    </collision>
  </link>
  <joint name="joint_8.0" type="revolute">
    <axis xyz="0 0 1"/>
    <limit effort="10" lower="-0.47" upper="0.47" velocity="3.14"/>
    <parent link="allegro_base_link"/>
    <child link="link_8.0"/>
    <origin rpy="0.08726646255 0 0" xyz="0 -0.0435 -0.001542"/>
  </joint>
  <link name="link_9.0">
    <inertial>
      <mass value="0.065"/>
      <origin xyz="0 0 0" rpy="0 0 0"/>
      <inertia ixx="7.95654166667e-05" ixy="1.7199e-05" ixz="8.75875e-06" iyy="2.47088833333e-05" iyz="2.413125e-05" izz="7.95654166667e-05"/>
    </inertial>
    <visual>
      <geometry>
        <mesh filename="../../hands/allegro_hand/meshes/visual/link_1.0.obj"/>
      </geometry>
    </visual>
    <collision>
      <geometry>
        <box size="0.0196 0.0275 0.054"/>
      </geometry>
      <origin rpy="0 0 0" xyz="0 0 0.027"/>
    </collision>
  </link>
  <joint name="joint_9.0" type="revolute">
    <limit effort="10" lower="-0.196" upper="1.61" velocity="3.14"/>
    <axis xyz="0 1 0"/>
    <parent link="link_8.0"/>
    <child link="link_9.0"/>
    <origin xyz="0 0 0.0164"/>
  </joint>
  <link name="link_10.0">
    <inertial>
      <mass value="0.0355"/>
      <origin xyz="0 0 0" rpy="0 0 0"/>
      <inertia ixx="2.63979183333e-05" ixy="6.67968e-06" ixz="4.783625e-06" iyy="1.34948516667e-05" iyz="9.372e-06" izz="2.63979183333e-05"/>
    </inertial>
    <visual>
      <geometry>
        <mesh filename="../../hands/allegro_hand/meshes/visual/link_2.0.obj"/>
      </geometry>
    </visual>
    <collision>
      <geometry>
        <box size="0.0196 0.0275 0.0384"/>
      </geometry>
      <origin rpy="0 0 0" xyz="0 0 0.0192"/>
    </collision>
  </link>
  <joint name="joint_10.0" type="revolute">
    <axis xyz="0 1 0"/>
    <limit effort="10" lower="-0.174" upper="1.709" velocity="3.14"/>
    <parent link="link_9.0"/>
    <child link="link_10.0"/>
    <origin xyz="0 0 0.054"/>
  </joint>
  <link name="link_11.0">
    <inertial>
      <mass value="0.0096"/>
      <origin xyz="0 0 0" rpy="0 0 0"/>
      <inertia ixx="4.701248e-06" ixy="1.255968e-06" ixz="1.2936e-06" iyy="3.649312e-06" iyz="1.7622e-06" izz="4.701248e-06"/>
    </inertial>
    <visual>
      <geometry>
        <mesh filename="../../hands/allegro_hand/meshes/visual/link_3.0.obj"/>
      </geometry>
    </visual>
    <collision>
      <geometry>
        <box size="0.0196 0.0269 0.022"/>
      </geometry>
      <origin rpy="0 0 0" xyz="0 0 0.0047"/>
    </collision>
  </link>
  <joint name="joint_11.0" type="revolute">
    <axis xyz="0 1 0"/>
    <limit effort="10" lower="-0.227" upper="1.618" velocity="3.14"/>
    <parent link="link_10.0"/>
    <child link="link_11.0"/>
    <origin xyz="0 0 0.0384"/>
  </joint>
  <link name="link_11.0_tip">
    <inertial>
      <mass value="0.0168"/>
      <origin xyz="0 0 0" rpy="0 0 0"/>
      <inertia ixx="9.68e-07" ixy="0" ixz="0" iyy="9.68e-07" iyz="0" izz="9.68e-07"/>
    </inertial>
    <visual>
      <origin rpy="0 0 0" xyz="0 0 -0.012"/>
      <geometry>
        <mesh filename="../../hands/allegro_hand/meshes/visual/link_tip.obj"/>
      </geometry>
    </visual>
    <collision>
      <origin rpy="0 0 0" xyz="0 0 -0.012"/>
      <geometry>
        <mesh filename="../../hands/allegro_hand/meshes/collision/link_tip.obj"/>
      </geometry>
    </collision>
  </link>
  <joint name="joint_11.0_tip" type="fixed">
    <parent link="link_11.0"/>
    <child link="link_11.0_tip"/>
    <origin rpy="0 0 0" xyz="0 0 0.0387"/>
  </joint> <!-- THUMB -->
  <link name="link_12.0">
    <inertial>
      <mass value="0.0176"/>
      <origin xyz="0 0 0" rpy="0 0 0"/>
      <inertia ixx="1.89273333333e-5" ixy="7.16716e-06" ixz="5.35568e-06" iyy="1.43008213333e-05" iyz="6.8068e-06" izz="1.89273333333e-05"/>
    </inertial>
    <visual>
      <geometry>
        <mesh filename="../../hands/allegro_hand/meshes/visual/link_12.0_right.obj"/>
      </geometry>
    </visual>
    <collision>
      <geometry>
        <box size="0.0358 0.034 0.0455"/>
      </geometry>
      <origin rpy="0 0 0" xyz="-0.0179 0.009 0.0145"/>
    </collision>
  </link>
  <joint name="joint_12.0" type="revolute">
    <axis xyz="-1 0 0"/>
    <limit effort="10" lower="0.263" upper="1.396" velocity="3.14"/>
    <parent link="allegro_base_link"/>
    <child link="link_12.0"/>
    <origin rpy="0 -1.65806278845 -1.5707963259" xyz="-0.0182 0.019333 -0.045987"/>
  </joint>
  <link name="link_13.0">
    <inertial>
      <mass value="0.0119"/>
      <origin xyz="0 0 0" rpy="0 0 0"/>
      <inertia ixx="4.24250866667e-06" ixy="1.032087e-06" ixz="1.603525e-06" iyy="4.52362633333e-06" iyz="1.44808125e-06" izz="4.24250866667e-06"/>
    </inertial>
    <visual>
      <geometry>
        <mesh filename="../../hands/allegro_hand/meshes/visual/link_13.0.obj"/>
      </geometry>
    </visual>
    <collision>
      <geometry>
        <box size="0.0196 0.0275 0.0177"/>
      </geometry>
      <origin rpy="0 0 0" xyz="0 0 0.00885"/>
    </collision>
  </link>
  <joint name="joint_13.0" type="revolute">
    <axis xyz="0 0 1"/>
    <limit effort="10" lower="-0.105" upper="1.163" velocity="3.14"/>
    <parent link="link_12.0"/>
    <child link="link_13.0"/>
    <origin xyz="-0.027 0.005 0.0399"/>
  </joint>
  <link name="link_14.0">
    <inertial>
      <mass value="0.038"/>
      <origin xyz="0 0 0" rpy="0 0 0"/>
      <inertia ixx="4.30439933333e-05" ixy="9.57068e-06" ixz="5.1205e-06" iyy="1.44451933333e-05" iyz="1.342825e-05" izz="4.30439933333e-05"/>
    </inertial>
    <visual>
      <geometry>
        <mesh filename="../../hands/allegro_hand/meshes/visual/link_14.0.obj"/>
      </geometry>
    </visual>
    <collision>
      <geometry>
        <box size="0.0196 0.0275 0.0514"/>
      </geometry>
      <origin rpy="0 0 0" xyz="0 0 0.0257"/>
    </collision>
  </link>
  <joint name="joint_14.0" type="revolute">
    <axis xyz="0 1 0"/>
    <limit effort="10" lower="-0.189" upper="1.644" velocity="3.14"/>
    <parent link="link_13.0"/>
    <child link="link_14.0"/>
    <origin xyz="0 0 0.0177"/>
  </joint>
  <link name="link_15.0">
    <inertial>
      <mass value="0.0388"/>
      <origin xyz="0 0 0" rpy="0 0 0"/>
      <inertia ixx="3.29223173333e-05" ixy="8.042076e-06" ixz="5.2283e-06" iyy="1.47493026667e-5" iyz="1.1283525e-5" izz="3.29223173333e-05"/>
    </inertial>
    <visual>
      <geometry>
        <mesh filename="../../hands/allegro_hand/meshes/visual/link_15.0.obj"/>
      </geometry>
    </visual>
    <collision>
      <geometry>
        <box size="0.0196 0.0269 0.04"/>
      </geometry>
      <origin rpy="0 0 0" xyz="0 0 0.01125"/>
    </collision>
  </link>
  <joint name="joint_15.0" type="revolute">
    <axis xyz="0 1 0"/>
    <limit effort="10" lower="-0.162" upper="1.719" velocity="3.14"/>
    <parent link="link_14.0"/>
    <child link="link_15.0"/>
    <origin xyz="0 0 0.0514"/>
  </joint>
  <link name="link_15.0_tip">
    <inertial>
      <mass value="0.0168"/>
      <origin xyz="0 0 0" rpy="0 0 0"/>
      <inertia ixx="9.68e-07" ixy="0" ixz="0" iyy="9.68e-07" iyz="0" izz="9.68e-07"/>
    </inertial>
    <visual>
      <origin rpy="0 0 0" xyz="0 0 -0.012"/>
      <geometry>
        <mesh filename="../../hands/allegro_hand/meshes/visual/link_tip.obj"/>
      </geometry>
    </visual>
    <collision>
      <origin rpy="0 0 0" xyz="0 0 -0.012"/>
      <geometry>
        <mesh filename="../../hands/allegro_hand/meshes/collision/link_tip.obj"/>
      </geometry>
    </collision>
  </link>
  <joint name="joint_15.0_tip" type="fixed">
    <parent link="link_15.0"/>
    <child link="link_15.0_tip"/>
    <origin rpy="0 0 0" xyz="0 0 0.0543"/>
  </joint>

</robot>

